Workbook

Sheet 📋 使用说明
A1: 菲格洛亚 FIGUEROA — BabyCat 财务对账工具包
A2: 版本 v1.0 · 生成日期 2026-08-11 · 数据期间 2026年5月—7月（含2025年摩点众筹 / 展会历史事项）
A4: ① 公司背景
A5: 菲格洛亚（FIGUEROA）为 AI 原生潮玩公司，主打 IP「BabyCat」毛绒盲盒——8 个猫品种角色（6 常规款 + 2 隐藏款）。
A6: 渠道覆盖：名创优品 / TOPTOY / KKV / 九木杂物社 / 沃尔玛 / 抖音电商 / TikTok 跨境 / 区域经销；
A7: 并先后在摩点平台发起众筹（三阶段结算，平台服务费 6%），参加 CTE、HTE 等潮玩展会。
A9: ② 工作簿结构（15 张表）
A10: 工作表 | B10: 内容说明 | C10: 类型
A11: 📋 使用说明 | B11: 本页：版本、结构索引、对账流程、口径与图例 | C11: 工具
A12: 🎨 商品目录 | B12: BabyCat 全系 24 个 SKU：零售价 / 经销价 | C12: 数据
A13: 👩‍🎨 艺术家主数据 | B13: 8 位艺术家、关联 SKU、分成比例与预计月版税 | C13: 数据
A14: 📦 销售出库 | B14: 45 笔销售单（含退货冲销，红色标识），账期与到期日 | C14: 数据
A15: 🏪 Sell-Through | B15: 经销商门店动销 25 条，与出库口径相互印证 | C15: 数据
A16: 💰 银行回款 | B16: 22 笔银行回款，按付款方名称自动匹配经销商（辅助列可隐藏） | C16: 数据
A17: 🎯 摩点众筹结算 | B17: 三阶段结算汇总、平台服务费 6% 测算、112 笔支持明细抽样 | C17: 分析
A18: 🔗 经销商对账 | B18: 核心表：SUMIF 跨表计算应收/已回/差异/状态 + 待核对事项 | C18: 分析
A19: 🎨 艺术家版税结算 | B19: 关联 SKU 销售实收 × 分成比例，SUMIF 公式引用销售出库 | C19: 分析
A20: 🎪 展会核算 | B20: 3 场展会收入费用与毛利率（含综合毛利率） | C20: 数据
A21: 📊 Dashboard | B21: KPI 卡片、经销商应收vs已回柱状图、月度趋势折线图、账龄分析 | C21: 仪表盘
... A25: 🧾 费用报销审核 | B25: 10 笔示例报销，自动校验发票金额差异与 OA 审批 | C25: 分析
A27: ③ 对账工作流程
A28: 1. 导出数据：销售出库 / 门店动销 / 银行回款 / 众筹结算 / 展会收入 / 合同（CSV 落盘到 ../data/）；
A29: 2. 回款匹配：脚本按付款方名称自动匹配经销商（名称一致 → 规范化一致 → 包含匹配，如『酷乐潮玩（北京）贸易公司』）；
A30: 3. 生成对账：『🔗 经销商对账』按经销商汇总应收（SUMIF 销售出库实收）与已回（SUMIF 银行回款辅助列），计算差异与状态；
A31: 4. 处理差异：在『待核对事项』逐条核实（部分回款 / 超额回款 / 抹零 / 汇兑 / 退货冲销 / 逾期未回）；
A32: 5. 平行结算：摩点众筹三阶段核销、艺术家版税计提、展会收支毛利、费用报销复核；
A33: 6. 归档交接：按『📦 代账交接清单』整理凭证、对账单与发票，移交代账公司。
A35: ④ 口径说明
A36: 应收口径：销售出库『实收金额』（= 金额 × 折扣率），退货冲销为负数自动冲减；
A37: 已回口径：银行回款金额，按付款方自动匹配经销商后汇总（不含众筹/展会等非经销回款）；
A38: 匹配状态：|应收-已回| < 0.01 → 已匹配（绿）；已回>0 但存在差异 → 部分/超额回款（黄）；已回=0 → 未回款（红）；
A39: 众筹口径：应结算金额为平台扣除服务费后的净额，服务费按 6% 倒算（毛额=净额/0.94）；
... A53: · 打印已设置为横向、适应页宽并重复表头行，可直接打印存档。

Sheet 🎨 商品目录
A1: 🎨 商品目录 — BabyCat 毛绒盲盒及周边（24 款）
A2: 零售价 = 建议零售价；经销价 = 渠道供货价；盲盒随机出货，明盒指定角色，端盒 6 只不重复。
A3: SKU编码 | B3: 规格编码 | C3: 商品名称 | D3: 品类 | E3: 零售价 | F3: 经销价
A4: SKU-001 | B4: BLIND-01 | C4: BabyCat随机单盒（盲盒早鸟） | D4: 盲盒 | E4: 89 | F4: 69
A5: SKU-002 | B5: BLIND-02 | C5: BabyCat随机单盒（盲盒常规） | D5: 盲盒 | E5: 95 | F5: 69
A6: SKU-003 | B6: OPEN-BC-01 | C6: BabyCat明盒·橘影神偷（橘猫） | D6: 明盒 | E6: 100 | F6: 69
A7: SKU-004 | B7: OPEN-BC-02 | C7: BabyCat明盒·折耳骑士（英短折耳） | D7: 明盒 | E7: 100 | F7: 69
A8: SKU-005 | B8: OPEN-BC-03 | C8: BabyCat明盒·笨笨博士（布偶猫） | D8: 明盒 | E8: 100 | F8: 69
A9: SKU-006 | B9: OPEN-BC-04 | C9: BabyCat明盒·奶牛猫（奶牛猫） | D9: 明盒 | E9: 100 | F9: 69
A10: SKU-007 | B10: OPEN-BC-05 | C10: BabyCat明盒·波斯猫（波斯猫） | D10: 明盒 | E10: 100 | F10: 69
A11: SKU-008 | B11: OPEN-BC-06 | C11: BabyCat明盒·软萌夹锁（德文卷毛） | D11: 明盒 | E11: 100 | F11: 69
A12: SKU-009 | B12: CP-01 | C12: BabyCat CP对盒·橘影神偷×折耳骑士 | D12: CP对盒 | E12: 184 | F12: 138
A13: SKU-010 | B13: CP-02 | C13: BabyCat CP对盒·笨笨博士×软萌夹锁 | D13: CP对盒 | E13: 184 | F13: 138
A14: SKU-011 | B14: CP-03 | C14: BabyCat CP对盒·奶牛猫×波斯猫 | D14: CP对盒 | E14: 184 | F14: 138
A15: SKU-012 | B15: ENDBOX | C15: BabyCat端盒（6只不重复·常规款全套） | D15: 端盒 | E15: 546 | F15: 414
... A27: SKU-024 | B27: ACC-10 | C27: BabyCatBabyCat毛绒抱枕（30cm） | D27: 抱枕 | E27: 99 | F27: 45

Sheet 👩‍🎨 艺术家主数据
A1: 👩‍🎨 艺术家主数据（8 位）
A2: 预计月版税 = 2026年5-7月关联SKU销售实收月均 × 分成比例（静态测算；正式计提见『🎨 艺术家版税结算』）。
A3: 艺术家编码 | B3: 艺术家姓名 | C3: 身份类型 | D3: 关联SKU | E3: 分成比例 | F3: 结算方式 | G3: 当期销售实收(5-7月) | H3: 预计月版税 | I3: 备注
A4: AR-001 | B4: 林小喵 | C4: 独立潮玩设计师 | D4: BC-01,BC-07 | E4: 0.08 | F4: 销售后结算 | G4: 13580 | H4: 362.13 | I4: BC-07 隐藏款随盲盒/套装随机出货，无独立销售规格，建议按套盒分摊口径另行测算
A5: AR-002 | B5: 陈卷卷 | C5: 自由插画师 | D5: BC-02 | E5: 0.07 | F5: 销售后结算 | G5: 0 | H5: 0 | I5: BC-02 当期无对应销售规格
A6: AR-003 | B6: 周布布 | C6: 猫主题IP创作者 | D6: BC-03,BC-06 | E6: 0.08 | F6: 销售后结算 | G6: 16250 | H6: 433.33 | I6: BC-06 当期无对应销售规格
A7: AR-004 | B7: 刘星野 | C7: 新锐玩具设计师 | D7: BC-04,BC-05 | E7: 0.07 | F7: 销售后结算 | G7: 0 | H7: 0 | I7: BC-04 当期无对应销售规格；BC-05 当期无对应销售规格
A8: AR-005 | B8: 赵小喵 | C8: 小红书潮玩博主 | D8: BC-08 | E8: 0.1 | F8: 预付+结算 | G8: 0 | H8: 0 | I8: BC-08 隐藏款随盲盒/套装随机出货，无独立销售规格，建议按套盒分摊口径另行测算
A9: AR-006 | B9: 黄多多 | C9: 在校艺术生/草根画手 | D9: BC-ACC-01,BC-ACC-02 | E9: 0.06 | F9: 销售后结算 | G9: 20855 | H9: 417.1 | I9: BC-ACC-01 与销售规格 ACC-01 编码不一致（疑缺BC前缀），本期按映射计入，建议与艺术家确认口径；BC-ACC-02 与销售规格 ACC-02 编码不一致（疑缺BC前缀），本期按映射计入，建议与艺术家确认口径
A10: AR-007 | B10: 何梦鹿 | C10: 自由职业插画师 | D10: BC-ACC-03,BC-ACC-04 | E10: 0.06 | F10: 销售后结算 | G10: 11600 | H10: 232 | I10: BC-ACC-03 当期无对应销售规格；BC-ACC-04 与销售规格 ACC-04 编码不一致（疑缺BC前缀），本期按映射计入，建议与艺术家确认口径
A11: AR-008 | B11: 杨桃桃 | C11: 纹身师兼玩具涂装师 | D11: BC-ACC-05,BC-ACC-06 | E11: 0.06 | F11: 销售后结算 | G11: 9215 | H11: 184.3 | I11: BC-ACC-05 当期无对应销售规格；BC-ACC-06 与销售规格 ACC-06 编码不一致（疑缺BC前缀），本期按映射计入，建议与艺术家确认口径

Sheet 📦 销售出库
A1: 📦 销售出库单（45 笔，含退货冲销）
A2: 实收金额 = 金额 × 折扣率；到期日 = 开单日期 + 账期天数；红色行 = 负数（退货冲销）。
A3: 销售单号 | B3: 开单日期 | C3: 经销商编码 | D3: 经销商名称 | E3: SKU编码 | F3: 商品名称 | G3: 数量 | H3: 单价 | I3: 金额 | J3: 折扣率 | K3: 实收金额 | L3: 账期天数 | M3: 到期日 | N3: 批次类型 | O3: 备注
A4: SO-20260510-001 | B4: 46152 | C4: DE-001 | D4: 名创优品（广州）有限责任公司 | E4: BLIND-02 | F4: BabyCat随机单盒（盲盒常规） | G4: 200 | H4: 95 | I4: 19000 | J4: 0.97 | K4: 18430 | L4: 45 | M4: 46197 | N4: 首单试产 | O4: BabyCat首轮铺货试产
A5: SO-20260510-002 | B5: 46152 | C5: DE-001 | D5: 名创优品（广州）有限责任公司 | E5: ENDBOX | F5: BabyCat端盒（6只不重复·常规款全套） | G5: 100 | H5: 546 | I5: 54600 | J5: 0.97 | K5: 52962 | L5: 45 | M5: 46197 | N5: 首单试产 | O5: 端盒同步试产
A6: SO-20260510-003 | B6: 46152 | C6: DE-001 | D6: 名创优品（广州）有限责任公司 | E6: OPEN-BC-01 | F6: BabyCat明盒·橘影神偷（橘猫） | G6: 60 | H6: 100 | I6: 6000 | J6: 0.97 | K6: 5820 | L6: 45 | M6: 46197 | N6: 首单试产
A7: SO-20260605-004 | B7: 46178 | C7: DE-001 | D7: 名创优品（广州）有限责任公司 | E7: BLIND-02 | F7: BabyCat随机单盒（盲盒常规） | G7: 500 | H7: 95 | I7: 47500 | J7: 0.97 | K7: 46075 | L7: 45 | M7: 46223 | N7: 快反追单 | O7: 销售超预期→追单（场景1a）
A8: SO-20260605-005 | B8: 46178 | C8: DE-001 | D8: 名创优品（广州）有限责任公司 | E8: ENDBOX | F8: BabyCat端盒（6只不重复·常规款全套） | G8: 200 | H8: 546 | I8: 109200 | J8: 0.97 | K8: 105924 | L8: 45 | M8: 46223 | N8: 快反追单 | O8: 端盒追单（场景1b）
A9: SO-20260605-006 | B9: 46178 | C9: DE-001 | D9: 名创优品（广州）有限责任公司 | E9: ACC-01 | F9: BabyCat毛绒挂件·橘影神偷 | G9: 300 | H9: 39 | I9: 11700 | J9: 0.97 | K9: 11349 | L9: 45 | M9: 46223 | N9: 快反追单 | O9: 挂件追单（场景1c）
A10: SO-20260708-007 | B10: 46211 | C10: DE-001 | D10: 名创优品（广州）有限责任公司 | E10: BLIND-02 | F10: BabyCat随机单盒（盲盒常规） | G10: 800 | H10: 95 | I10: 76000 | J10: 0.95 | K10: 72200 | L10: 45 | M10: 46256 | N10: 二次追单 | O10: 暑期促销追单
A11: SO-20260708-008 | B11: 46211 | C11: DE-001 | D11: 名创优品（广州）有限责任公司 | E11: OPEN-BC-03 | F11: BabyCat明盒·笨笨博士（布偶猫） | G11: 120 | H11: 100 | I11: 12000 | J11: 0.95 | K11: 11400 | L11: 45 | M11: 46256 | N11: 二次追单
A12: SO-20260515-009 | B12: 46157 | C12: DE-002 | D12: 酷乐潮玩（北京）贸易有限公司 | E12: BLIND-01 | F12: BabyCat随机单盒（盲盒早鸟） | G12: 150 | H12: 89 | I12: 13350 | J12: 0.97 | K12: 12949.5 | L12: 30 | M12: 46187 | N12: 首单试产
A13: SO-20260515-010 | B13: 46157 | C13: DE-002 | D13: 酷乐潮玩（北京）贸易有限公司 | E13: ENDBOX | F13: BabyCat端盒（6只不重复·常规款全套） | G13: 80 | H13: 546 | I13: 43680 | J13: 0.97 | K13: 42369.6 | L13: 30 | M13: 46187 | N13: 首单试产
A14: SO-20260612-011 | B14: 46185 | C14: DE-002 | D14: 酷乐潮玩（北京）贸易有限公司 | E14: BLIND-02 | F14: BabyCat随机单盒（盲盒常规） | G14: 400 | H14: 95 | I14: 38000 | J14: 0.97 | K14: 36860 | L14: 30 | M14: 46215 | N14: 快反追单
A15: SO-20260612-012 | B15: 46185 | C15: DE-002 | D15: 酷乐潮玩（北京）贸易有限公司 | E15: OPEN-BC-01 | F15: BabyCat明盒·橘影神偷（橘猫） | G15: 80 | H15: 100 | I15: 8000 | J15: 0.97 | K15: 7760 | L15: 30 | M15: 46215 | N15: 快反追单
A16: SO-20260710-013 | B16: 46213 | C16: DE-002 | D16: 酷乐潮玩（北京）贸易有限公司 | E16: BLIND-02 | F16: BabyCat随机单盒（盲盒常规） | G16: 600 | H16: 95 | I16: 57000 | J16: 0.95 | K16: 54150 | L16: 30 | M16: 46243 | N16: 二次追单
A17: SO-20260520-014 | B17: 46162 | C17: DE-003 | D17: TOPTOY（广州）文化发展有限公司 | E17: BLIND-01 | F17: BabyCat随机单盒（盲盒早鸟） | G17: 200 | H17: 89 | I17: 17800 | J17: 0.97 | K17: 17266 | L17: 45 | M17: 46207 | N17: 首单试产
A18: SO-20260520-015 | B18: 46162 | C18: DE-003 | D18: TOPTOY（广州）文化发展有限公司 | E18: ENDBOX | F18: BabyCat端盒（6只不重复·常规款全套） | G18: 100 | H18: 546 | I18: 54600 | J18: 0.97 | K18: 52962 | L18: 45 | M18: 46207 | N18: 首单试产
A19: SO-20260618-016 | B19: 46191 | C19: DE-003 | D19: TOPTOY（广州）文化发展有限公司 | E19: BLIND-02 | F19: BabyCat随机单盒（盲盒常规） | G19: 500 | H19: 95 | I19: 47500 | J19: 0.97 | K19: 46075 | L19: 45 | M19: 46236 | N19: 快反追单
A20: SO-20260618-017 | B20: 46191 | C20: DE-003 | D20: TOPTOY（广州）文化发展有限公司 | E20: ENDBOX | F20: BabyCat端盒（6只不重复·常规款全套） | G20: 250 | H20: 546 | I20: 136500 | J20: 0.97 | K20: 132405 | L20: 45 | M20: 46236 | N20: 快反追单
A21: SO-20260715-018 | B21: 46218 | C21: DE-003 | D21: TOPTOY（广州）文化发展有限公司 | E21: BLIND-02 | F21: BabyCat随机单盒（盲盒常规） | G21: 700 | H21: 95 | I21: 66500 | J21: 0.95 | K21: 63175 | L21: 45 | M21: 46263 | N21: 二次追单
A22: SO-20260508-019 | B22: 46150 | C22: DE-004 | D22: 广州KK馆贸易有限公司 | E22: BLIND-01 | F22: BabyCat随机单盒（盲盒早鸟） | G22: 100 | H22: 89 | I22: 8900 | J22: 0.97 | K22: 8633 | L22: 30 | M22: 46180 | N22: 首单试产
... A24: SO-20260610-021 | B24: 46183 | C24: DE-004 | D24: 广州KK馆贸易有限公司 | E24: ACC-02 | F24: BabyCat亚克力立牌·BabyCat全家福 | G24: 200 | H24: 49 | I24: 9800 | J24: 0.97 | K24: 9506 | L24: 30 | M24: 46213 | N24: 快反追单
A25: SO-20260705-022 | B25: 46208 | C25: DE-004 | D25: 广州KK馆贸易有限公司 | E25: BLIND-02 | F25: BabyCat随机单盒（盲盒常规） | G25: -30 | H25: 95 | I25: -2850 | J25: 1 | K25: -2850 | L25: 30 | M25: 46238 | N25: 退货冲销 | O25: 品质问题退货（场景8）
A26: SO-20260705-023 | B26: 46208 | C26: DE-004 | D26: 广州KK馆贸易有限公司 | E26: BLIND-02 | F26: BabyCat随机单盒（盲盒常规） | G26: 160 | H26: 95 | I26: 15200 | J26: 0.95 | K26: 14440 | L26: 30 | M26: 46238 | N26: 常规补货
A27: SO-20260512-024 | B27: 46154 | C27: DE-005 | D27: 上海晨光文具股份有限公司（九木杂物社） | E27: BLIND-01 | F27: BabyCat随机单盒（盲盒早鸟） | G27: 80 | H27: 89 | I27: 7120 | J27: 0.97 | K27: 6906.4 | L27: 60 | M27: 46214 | N27: 首单试产
A28: SO-20260512-025 | B28: 46154 | C28: DE-005 | D28: 上海晨光文具股份有限公司（九木杂物社） | E28: ENDBOX | F28: BabyCat端盒（6只不重复·常规款全套） | G28: 40 | H28: 546 | I28: 21840 | J28: 0.97 | K28: 21184.8 | L28: 60 | M28: 46214 | N28: 首单试产
A29: SO-20260608-026 | B29: 46181 | C29: DE-005 | D29: 上海晨光文具股份有限公司（九木杂物社） | E29: BLIND-02 | F29: BabyCat随机单盒（盲盒常规） | G29: 250 | H29: 95 | I29: 23750 | J29: 0.97 | K29: 23037.5 | L29: 60 | M29: 46241 | N29: 快反追单
A30: SO-20260608-027 | B30: 46181 | C30: DE-005 | D30: 上海晨光文具股份有限公司（九木杂物社） | E30: OPEN-BC-03 | F30: BabyCat明盒·笨笨博士（布偶猫） | G30: 50 | H30: 100 | I30: 5000 | J30: 0.97 | K30: 4850 | L30: 60 | M30: 46241 | N30: 快反追单
A31: SO-20260505-028 | B31: 46147 | C31: DE-006 | D31: 沃尔玛（中国）投资有限公司 | E31: BLIND-02 | F31: BabyCat随机单盒（盲盒常规） | G31: 200 | H31: 95 | I31: 19000 | J31: 0.95 | K31: 18050 | L31: 60 | M31: 46207 | N31: 首单试产
A32: SO-20260505-029 | B32: 46147 | C32: DE-006 | D32: 沃尔玛（中国）投资有限公司 | E32: ENDBOX | F32: BabyCat端盒（6只不重复·常规款全套） | G32: 100 | H32: 546 | I32: 54600 | J32: 0.95 | K32: 51870 | L32: 60 | M32: 46207 | N32: 首单试产
A33: SO-20260601-030 | B33: 46174 | C33: DE-006 | D33: 沃尔玛（中国）投资有限公司 | E33: BLIND-02 | F33: BabyCat随机单盒（盲盒常规） | G33: 350 | H33: 95 | I33: 33250 | J33: 0.95 | K33: 31587.5 | L33: 60 | M33: 46234 | N33: 快反追单
A34: SO-20260518-031 | B34: 46160 | C34: DE-007 | D34: 抖音电商（官方旗舰店） | E34: BLIND-02 | F34: BabyCat随机单盒（盲盒常规） | G34: 300 | H34: 95 | I34: 28500 | J34: 1 | K34: 28500 | L34: 15 | M34: 46175 | N34: 平台铺货
A35: SO-20260518-032 | B35: 46160 | C35: DE-007 | D35: 抖音电商（官方旗舰店） | E35: ALLIN | F35: BabyCat ALL-IN套装（6常规+2隐藏） | G35: 50 | H35: 680 | I35: 34000 | J35: 1 | K35: 34000 | L35: 15 | M35: 46175 | N35: 平台铺货
A36: SO-20260620-033 | B36: 46193 | C36: DE-007 | D36: 抖音电商（官方旗舰店） | E36: BLIND-02 | F36: BabyCat随机单盒（盲盒常规） | G36: 500 | H36: 95 | I36: 47500 | J36: 1 | K36: 47500 | L36: 15 | M36: 46208 | N36: 快反追单
A37: SO-20260620-034 | B37: 46193 | C37: DE-007 | D37: 抖音电商（官方旗舰店） | E37: ACC-04 | F37: BabyCat摇摇乐钥匙扣·折耳骑士 | G37: 400 | H37: 29 | I37: 11600 | J37: 1 | K37: 11600 | L37: 15 | M37: 46208 | N37: 快反追单
A38: SO-20260601-035 | B38: 46174 | C38: DE-008 | D38: TikTok Shop（跨境） | E38: BLIND-02 | F38: BabyCat随机单盒（盲盒常规） | G38: 200 | H38: 95 | I38: 19000 | J38: 1 | K38: 19000 | L38: 30 | M38: 46204 | N38: 海外铺货 | O38: TikTok Shop US
A39: SO-20260601-036 | B39: 46174 | C39: DE-008 | D39: TikTok Shop（跨境） | E39: ALLIN | F39: BabyCat ALL-IN套装（6常规+2隐藏） | G39: 30 | H39: 680 | I39: 20400 | J39: 1 | K39: 20400 | L39: 30 | M39: 46204 | N39: 海外铺货
A40: SO-20260701-037 | B40: 46204 | C40: DE-008 | D40: TikTok Shop（跨境） | E40: BLIND-02 | F40: BabyCat随机单盒（盲盒常规） | G40: 350 | H40: 95 | I40: 33250 | J40: 1 | K40: 33250 | L40: 30 | M40: 46234 | N40: 快反追单 | O40: TikTok Shop US
A41: SO-20260525-038 | B41: 46167 | C41: DE-009 | D41: 广州潮玩前线贸易有限公司 | E41: BLIND-02 | F41: BabyCat随机单盒（盲盒常规） | G41: 120 | H41: 95 | I41: 11400 | J41: 0.97 | K41: 11058 | L41: 30 | M41: 46197 | N41: 首单试产
...

Sheet 🏪 Sell-Through
A1: 🏪 Sell-Through — 经销商门店动销（25 条）
A2: 寄售/经销渠道按月报送的终端动销数据，销售金额 = 销售数量 × 单价，与『📦 销售出库』口径相互印证。
A3: 报表编号 | B3: 报表月份 | C3: 经销商编码 | D3: SKU编码 | E3: 商品名称 | F3: 销售数量 | G3: 单价 | H3: 销售金额
A4: ST-202605-001 | B4: 46143 | C4: DE-001 | D4: BLIND-02 | E4: BabyCat随机单盒（盲盒常规） | F4: 180 | G4: 89 | H4: 16020
A5: ST-202605-002 | B5: 46143 | C5: DE-001 | D5: ENDBOX | E5: BabyCat端盒（6只不重复·常规款全套） | F5: 95 | G5: 546 | H5: 51870
A6: ST-202605-003 | B6: 46143 | C6: DE-001 | D6: OPEN-BC-01 | E6: BabyCat明盒·橘影神偷（橘猫） | F6: 55 | G6: 100 | H6: 5500
A7: ST-202606-004 | B7: 46174 | C7: DE-001 | D7: BLIND-02 | E7: BabyCat随机单盒（盲盒常规） | F7: 480 | G7: 89 | H7: 42720
A8: ST-202606-005 | B8: 46174 | C8: DE-001 | D8: ENDBOX | E8: BabyCat端盒（6只不重复·常规款全套） | F8: 190 | G8: 546 | H8: 103740
A9: ST-202606-006 | B9: 46174 | C9: DE-001 | D9: ACC-01 | E9: BabyCat毛绒挂件·橘影神偷 | F9: 280 | G9: 39 | H9: 10920
A10: ST-202607-007 | B10: 46204 | C10: DE-001 | D10: BLIND-02 | E10: BabyCat随机单盒（盲盒常规） | F10: 300 | G10: 89 | H10: 26700
A11: ST-202607-008 | B11: 46204 | C11: DE-001 | D11: OPEN-BC-03 | E11: BabyCat明盒·笨笨博士（布偶猫） | F11: 45 | G11: 100 | H11: 4500
A12: ST-202605-009 | B12: 46143 | C12: DE-002 | D12: BLIND-01 | E12: BabyCat随机单盒（盲盒早鸟） | F12: 140 | G12: 89 | H12: 12460
A13: ST-202605-010 | B13: 46143 | C13: DE-002 | D13: ENDBOX | E13: BabyCat端盒（6只不重复·常规款全套） | F13: 75 | G13: 546 | H13: 40950
A14: ST-202606-011 | B14: 46174 | C14: DE-002 | D14: BLIND-02 | E14: BabyCat随机单盒（盲盒常规） | F14: 380 | G14: 89 | H14: 33820
A15: ST-202607-012 | B15: 46204 | C15: DE-002 | D15: BLIND-02 | E15: BabyCat随机单盒（盲盒常规） | F15: 250 | G15: 89 | H15: 22250
... A28: ST-202606-025 | B28: 46174 | C28: DE-005 | D28: OPEN-BC-03 | E28: BabyCat明盒·笨笨博士（布偶猫） | F28: 45 | G28: 100 | H28: 4500

Sheet 💰 银行回款
A1: 💰 银行回款流水（22 笔）
A2: 按付款方名称自动匹配经销商（名称一致 / 规范化一致 / 包含匹配）；I 列为匹配结果，J 列为 SUMIF 辅助编码（可隐藏）。
A3: 回款单号 | B3: 到账日期 | C3: 付款方名称 | D3: 金额 | E3: 付款方式 | F3: 开户行 | G3: 交易流水号 | H3: 备注 | I3: 对账经销商(自动匹配) | J3: 经销商编码(辅助列)
A4: PM-20260801-001 | B4: 46235 | C4: 名创优品（广州）有限责任公司 | D4: 163348 | E4: 网银转账 | F4: 中国工商银行深圳前海支行 | G4: 3956260831832256 | H4: 6月货款合计 单号SO-20260605-004/SO-20260605-005/SO-20260605-006（场景1:多单合并） | I4: 名创优品（广州）有限责任公司 | J4: DE-001
A5: PM-20260803-002 | B5: 46237 | C5: TOPTOY（广州）文化发展有限公司 | D5: 50000 | E5: 网银转账 | F5: 中国工商银行深圳前海支行 | G5: 6747341224418040 | H5: 6月部分货款 单号SO-20260618-016（场景2:部分回款） | I5: TOPTOY（广州）文化发展有限公司 | J5: DE-003
A6: PM-20260701-003 | B6: 46204 | C6: 抖音电商（官方旗舰店） | D6: 30000 | E6: 网银转账 | F6: 中国工商银行深圳前海支行 | G6: 7633496704183093 | H6: 7月新品订货预付款（场景4:预付款） | I6: 抖音电商（官方旗舰店） | J6: DE-007
A7: PM-20260805-004 | B7: 46239 | C7: 广州潮玩前线贸易有限公司 | D7: 11978.83 | E7: 网银转账 | F7: 中国工商银行深圳前海支行 | G7: 6986708854616866 | H7: 7月货款 单号SO-20260720-044（场景5:抹零差异¥0.67） | I7: 广州潮玩前线贸易有限公司 | J7: DE-009
A8: PM-20260725-005 | B8: 46228 | C8: 酷乐潮玩（北京）贸易公司 | D8: 38848 | E8: 网银转账 | F8: 中国工商银行深圳前海支行 | G8: 4967854356581702 | H8: 6月货款 BabyCat盲盒+端盒（场景6:付款方名称不规范） | I8: 酷乐潮玩（北京）贸易有限公司 | J8: DE-002
A9: PM-20260801-006 | B9: 46235 | C9: 上海晨光文具股份有限公司（九木杂物社） | D9: 14520 | E9: 网银转账 | F9: 中国工商银行深圳前海支行 | G9: 2008867831427862 | H9: 5月货款 单号SO-20260512-024（场景7:逾期15天到账） | I9: 上海晨光文具股份有限公司（九木杂物社） | J9: DE-005
A10: PM-20260802-007 | B10: 46236 | C10: 广州KK馆贸易有限公司 | D10: 45280 | E10: 网银转账 | F10: 中国工商银行深圳前海支行 | G10: 6404576034975573 | H10: 6-7月货款（场景8:含退货冲销） | I10: 广州KK馆贸易有限公司 | J10: DE-004
A11: PM-20260720-008 | B11: 46223 | C11: 广州潮玩前线贸易有限公司 | D11: 11058 | E11: 网银转账 | F11: 中国工商银行深圳前海支行 | G11: 6137576807612845 | H11: （场景9:无备注自动匹配） | I11: 广州潮玩前线贸易有限公司 | J11: DE-009
A12: PM-20260722-009 | B12: 46225 | C12: 义乌萌物集贸易有限公司 | D12: 9214 | E12: 网银转账 | F12: 中国工商银行深圳前海支行 | G12: 1544452611893555 | H12: 5月货款（场景10:少付¥1.00） | I12: 义乌萌物集贸易有限公司 | J12: DE-010
A13: PM-20260620-010 | B13: 46193 | C13: 名创优品（广州）有限责任公司 | D13: 53820.8 | E13: 网银转账 | F13: 中国工商银行深圳前海支行 | G13: 2944180289693803 | H13: 5月BabyCat首轮试产货款 | I13: 名创优品（广州）有限责任公司 | J13: DE-001
A14: PM-20260625-011 | B14: 46198 | C14: 酷乐潮玩（北京）贸易有限公司 | D14: 26126.4 | E14: 网银转账 | F14: 中国工商银行深圳前海支行 | G14: 6337613985348779 | H14: 5月BabyCat试产货款 | I14: 酷乐潮玩（北京）贸易有限公司 | J14: DE-002
A15: PM-20260715-012 | B15: 46218 | C15: 抖音电商（官方旗舰店） | D15: 42560 | E15: 网银转账 | F15: 中国工商银行深圳前海支行 | G15: 3874043667498408 | H15: 5-6月平台结算（已扣佣金） | I15: 抖音电商（官方旗舰店） | J15: DE-007
... A25: PM-20260807-022 | B25: 46241 | C25: 义乌萌物集贸易有限公司 | D25: 30820 | E25: 网银转账 | F25: 中国工商银行深圳前海支行 | G25: 4099031231421026 | H25: 6-7月货款 | I25: 义乌萌物集贸易有限公司 | J25: DE-010

Sheet 🎯 摩点众筹结算
A1: 🎯 摩点众筹结算 — BabyCat 首轮众筹（2025.07–2026.02）
A2: 应结算金额为平台扣除服务费后的净额；服务费按 6% 倒算（毛额=净额/0.94）；支持明细为后台抽样 112 笔，与结算总额口径不同。
A4: ① 三阶段结算明细
A5: 结算编号 | B5: 申请日期 | C5: 结算阶段 | D5: 应结算金额 | E5: 到账日期 | F5: 实际到账 | G5: 状态 | H5: 备注
A6: MD-SETTLE-01 | B6: 45874 | C6: 首款（50%） | D6: 39778 | E6: 45879 | F6: 39778 | G6: 已到账 | H6: 众筹成功→首款实际到账（场景11:比理论¥41777少¥1999，因支持者退款）
A7: MD-SETTLE-02 | B7: 45981 | C7: 中款（30%） | D7: 25067 | E7: 45986 | F7: 25067 | G7: 已到账 | H7: 全部发货完成→中款到账
A8: MD-SETTLE-03 | B8: 46058 | C8: 尾款（20%） | D8: 16711 | E8: 46065 | F8: 16711 | G8: 已到账 | H8: 评价期满→尾款到账
A9: 合计 | C9: 三阶段合计 | D9: =SUM(D6:D8) | F9: =SUM(F6:F8) | G9: — | H9: 未到账=应结算-实际到账
A10: ② 平台服务费测算（摩点标准 6%）
A11: 项目 | B11: 金额（元） | C11: 说明
A12: 应结算总额（文件口径） | B12: =D9 | C12: 三阶段应结算合计（已扣服务费）
A13: 众筹认筹毛额（倒算） | B13: =ROUND(D9/0.94,2) | C13: 毛额 = 净额 ÷ (1-6%)
A14: 平台服务费（6%） | B14: =ROUND(D9/0.94*0.06,2) | C14: 认筹毛额 × 6%
A15: 服务费后净应收 | B15: =ROUND(D9/0.94*0.94,2) | C15: =应结算总额（两者应一致）
A16: 实际已到账 | B16: =F9 | C16: 银行实际到账合计
A17: 未到账 | B17: =ROUND(D9/0.94*0.94-F9,2) | C17: 0 表示三阶段全部结清
A19: ③ 支持明细汇总（后台抽样 112 笔）
A20: 档位名称 | B20: 支持笔数 | C20: 支持金额（元） | D20: 占比
A21: ALL-IN套装 | B21: 14 | C21: 9520 | D21: =14/112
A22: 端盒（6只） | B22: 14 | C22: 7644 | D22: =14/112
A23: CP对盒（常规） | B23: 14 | C23: 2576 | D23: =14/112
A24: CP对盒（早鸟） | B24: 14 | C24: 2464 | D24: =14/112
A25: 明盒（常规） | B25: 14 | C25: 1400 | D25: =14/112
A26: 单盒（常规） | B26: 14 | C26: 1330 | D26: =14/112
A27: 限量明盒（早鸟） | B27: 14 | C27: 1316 | D27: =14/112
A28: 随机单盒（早鸟） | B28: 14 | C28: 1246 | D28: =14/112
A29: 合计 | B29: =SUM(B21:B28) | C29: =SUM(C21:C28) | D29: 8 个档位
A31: 支付状态：已支付 112 笔 / 未支付 0 笔 | 发货状态：已发货 112 笔 / 未发货 0 笔
A33: ④ 支持明细（抽样）
A34: 支持编号 | B34: 支持日期 | C34: 支持者 | D34: 档位名称 | E34: 数量 | F34: 单价 | G34: 金额 | H34: 支付状态 | I34: 发货状态
A35: MD-2025070001 | B35: 45862 | C35: 张*欣 | D35: 随机单盒（早鸟） | E35: 1 | F35: 89 | G35: 89 | H35: 已支付 | I35: 已发货
A36: MD-2025070002 | B36: 45863 | C36: 李*然 | D36: 限量明盒（早鸟） | E36: 1 | F36: 94 | G36: 94 | H36: 已支付 | I36: 已发货
A37: MD-2025070003 | B37: 45877 | C37: 王*喵 | D37: 单盒（常规） | E37: 1 | F37: 95 | G37: 95 | H37: 已支付 | I37: 已发货
A38: MD-2025070004 | B38: 45875 | C38: 陈*豪 | D38: 明盒（常规） | E38: 1 | F38: 100 | G38: 100 | H38: 已支付 | I38: 已发货
A39: MD-2025070005 | B39: 45855 | C39: 刘*宇 | D39: CP对盒（早鸟） | E39: 1 | F39: 176 | G39: 176 | H39: 已支付 | I39: 已发货
A40: MD-2025070006 | B40: 45865 | C40: 赵*彤 | D40: CP对盒（常规） | E40: 1 | F40: 184 | G40: 184 | H40: 已支付 | I40: 已发货
A41: MD-2025070007 | B41: 45858 | C41: 周*远 | D41: 端盒（6只） | E41: 1 | F41: 546 | G41: 546 | H41: 已支付 | I41: 已发货
A42: MD-2025070008 | B42: 45879 | C42: 吴*琪 | D42: ALL-IN套装 | E42: 1 | F42: 680 | G42: 680 | H42: 已支付 | I42: 已发货
A43: MD-2025070009 | B43: 45868 | C43: 郑*杰 | D43: 随机单盒（早鸟） | E43: 1 | F43: 89 | G43: 89 | H43: 已支付 | I43: 已发货
A44: MD-2025070010 | B44: 45873 | C44: 钱*琳 | D44: 限量明盒（早鸟） | E44: 1 | F44: 94 | G44: 94 | H44: 已支付 | I44: 已发货
...

Sheet 🔗 经销商对账
A1: 🔗 经销商对账工作底稿（核心表）
A2: 应收 = SUMIF(销售出库实收金额, 经销商编码)；已回 = SUMIF(银行回款辅助列J, 经销商编码)；差异 = 应收 - 已回；匹配状态自动判断（绿=已匹配 / 黄=部分或超额 / 红=未回款）。
A3: 经销商编码 | B3: 经销商名称 | C3: 应收金额(销售实收) | D3: 门店销通金额 | E3: 已回款(银行) | F3: 差异(应收-已回) | G3: 匹配状态
A4: DE-001 | B4: 名创优品（广州）有限责任公司 | C4: =SUMIF('📦 销售出库'!$C$4:$C$48,$A4,'📦 销售出库'!$K$4:$K$48) | D4: =SUMIF('🏪 Sell-Through'!$C$4:$C$28,$A4,'🏪 Sell-Through'!$H$4:$H$28) | E4: =SUMIF('💰 银行回款'!$J$4:$J$25,$A4,'💰 银行回款'!$D$4:$D$25) | F4: =C4-E4 | G4: =IF(AND(E4>0,ABS(F4)<0.005),"已匹配",IF(E4>0,IF(F4<-0.005,"超额回款","部分回款"),"未回款"))
A5: DE-002 | B5: 酷乐潮玩（北京）贸易有限公司 | C5: =SUMIF('📦 销售出库'!$C$4:$C$48,$A5,'📦 销售出库'!$K$4:$K$48) | D5: =SUMIF('🏪 Sell-Through'!$C$4:$C$28,$A5,'🏪 Sell-Through'!$H$4:$H$28) | E5: =SUMIF('💰 银行回款'!$J$4:$J$25,$A5,'💰 银行回款'!$D$4:$D$25) | F5: =C5-E5 | G5: =IF(AND(E5>0,ABS(F5)<0.005),"已匹配",IF(E5>0,IF(F5<-0.005,"超额回款","部分回款"),"未回款"))
A6: DE-003 | B6: TOPTOY（广州）文化发展有限公司 | C6: =SUMIF('📦 销售出库'!$C$4:$C$48,$A6,'📦 销售出库'!$K$4:$K$48) | D6: =SUMIF('🏪 Sell-Through'!$C$4:$C$28,$A6,'🏪 Sell-Through'!$H$4:$H$28) | E6: =SUMIF('💰 银行回款'!$J$4:$J$25,$A6,'💰 银行回款'!$D$4:$D$25) | F6: =C6-E6 | G6: =IF(AND(E6>0,ABS(F6)<0.005),"已匹配",IF(E6>0,IF(F6<-0.005,"超额回款","部分回款"),"未回款"))
A7: DE-004 | B7: 广州KK馆贸易有限公司 | C7: =SUMIF('📦 销售出库'!$C$4:$C$48,$A7,'📦 销售出库'!$K$4:$K$48) | D7: =SUMIF('🏪 Sell-Through'!$C$4:$C$28,$A7,'🏪 Sell-Through'!$H$4:$H$28) | E7: =SUMIF('💰 银行回款'!$J$4:$J$25,$A7,'💰 银行回款'!$D$4:$D$25) | F7: =C7-E7 | G7: =IF(AND(E7>0,ABS(F7)<0.005),"已匹配",IF(E7>0,IF(F7<-0.005,"超额回款","部分回款"),"未回款"))
A8: DE-005 | B8: 上海晨光文具股份有限公司（九木杂物社） | C8: =SUMIF('📦 销售出库'!$C$4:$C$48,$A8,'📦 销售出库'!$K$4:$K$48) | D8: =SUMIF('🏪 Sell-Through'!$C$4:$C$28,$A8,'🏪 Sell-Through'!$H$4:$H$28) | E8: =SUMIF('💰 银行回款'!$J$4:$J$25,$A8,'💰 银行回款'!$D$4:$D$25) | F8: =C8-E8 | G8: =IF(AND(E8>0,ABS(F8)<0.005),"已匹配",IF(E8>0,IF(F8<-0.005,"超额回款","部分回款"),"未回款"))
A9: DE-006 | B9: 沃尔玛（中国）投资有限公司 | C9: =SUMIF('📦 销售出库'!$C$4:$C$48,$A9,'📦 销售出库'!$K$4:$K$48) | D9: =SUMIF('🏪 Sell-Through'!$C$4:$C$28,$A9,'🏪 Sell-Through'!$H$4:$H$28) | E9: =SUMIF('💰 银行回款'!$J$4:$J$25,$A9,'💰 银行回款'!$D$4:$D$25) | F9: =C9-E9 | G9: =IF(AND(E9>0,ABS(F9)<0.005),"已匹配",IF(E9>0,IF(F9<-0.005,"超额回款","部分回款"),"未回款"))
A10: DE-007 | B10: 抖音电商（官方旗舰店） | C10: =SUMIF('📦 销售出库'!$C$4:$C$48,$A10,'📦 销售出库'!$K$4:$K$48) | D10: =SUMIF('🏪 Sell-Through'!$C$4:$C$28,$A10,'🏪 Sell-Through'!$H$4:$H$28) | E10: =SUMIF('💰 银行回款'!$J$4:$J$25,$A10,'💰 银行回款'!$D$4:$D$25) | F10: =C10-E10 | G10: =IF(AND(E10>0,ABS(F10)<0.005),"已匹配",IF(E10>0,IF(F10<-0.005,"超额回款","部分回款"),"未回款"))
A11: DE-008 | B11: TikTok Shop（跨境） | C11: =SUMIF('📦 销售出库'!$C$4:$C$48,$A11,'📦 销售出库'!$K$4:$K$48) | D11: =SUMIF('🏪 Sell-Through'!$C$4:$C$28,$A11,'🏪 Sell-Through'!$H$4:$H$28) | E11: =SUMIF('💰 银行回款'!$J$4:$J$25,$A11,'💰 银行回款'!$D$4:$D$25) | F11: =C11-E11 | G11: =IF(AND(E11>0,ABS(F11)<0.005),"已匹配",IF(E11>0,IF(F11<-0.005,"超额回款","部分回款"),"未回款"))
A12: DE-009 | B12: 广州潮玩前线贸易有限公司 | C12: =SUMIF('📦 销售出库'!$C$4:$C$48,$A12,'📦 销售出库'!$K$4:$K$48) | D12: =SUMIF('🏪 Sell-Through'!$C$4:$C$28,$A12,'🏪 Sell-Through'!$H$4:$H$28) | E12: =SUMIF('💰 银行回款'!$J$4:$J$25,$A12,'💰 银行回款'!$D$4:$D$25) | F12: =C12-E12 | G12: =IF(AND(E12>0,ABS(F12)<0.005),"已匹配",IF(E12>0,IF(F12<-0.005,"超额回款","部分回款"),"未回款"))
A13: DE-010 | B13: 义乌萌物集贸易有限公司 | C13: =SUMIF('📦 销售出库'!$C$4:$C$48,$A13,'📦 销售出库'!$K$4:$K$48) | D13: =SUMIF('🏪 Sell-Through'!$C$4:$C$28,$A13,'🏪 Sell-Through'!$H$4:$H$28) | E13: =SUMIF('💰 银行回款'!$J$4:$J$25,$A13,'💰 银行回款'!$D$4:$D$25) | F13: =C13-E13 | G13: =IF(AND(E13>0,ABS(F13)<0.005),"已匹配",IF(E13>0,IF(F13<-0.005,"超额回款","部分回款"),"未回款"))
A14: 合计 | C14: =SUM(C4:C13) | D14: =SUM(D4:D13) | E14: =SUM(E4:E13) | F14: =C14-E14
A16: ⚠ 待核对事项（差异清单）
A17: 仅列出 |差异| ≥ 0.01 的经销商；黄色=部分/超额回款，红色=未回款。以下金额为按公式口径自动计算的 Python 校验值，与 Excel 公式结果一致。
A18: · 【DE-001】名创优品（广州）有限责任公司：应收 ¥324,160.00 / 已回 ¥289,848.80 / 差异 ¥34,311.20（回款率 89%）→ 部分回款，建议按销售单逐笔核销回款备注）
A19: · 【DE-002】酷乐潮玩（北京）贸易有限公司：应收 ¥154,089.10 / 已回 ¥116,274.40 / 差异 ¥37,814.70（回款率 75%）→ 部分回款，建议按销售单逐笔核销回款备注（回款备注：6月货款 BabyCat盲盒+端盒（场景6:付款方名称不规范））
A20: · 【DE-003】TOPTOY（广州）文化发展有限公司：应收 ¥311,883.00 / 已回 ¥87,056.00 / 差异 ¥224,827.00（回款率 28%）→ 部分回款，建议按销售单逐笔核销回款备注（回款备注：6月部分货款 单号SO-20260618-016（场景2:部分回款））
A21: · 【DE-004】广州KK馆贸易有限公司：应收 ¥57,374.00 / 已回 ¥54,010.00 / 差异 ¥3,364.00（回款率 94%）→ 小额差异，建议核对抹零 / 手续费 / 四舍五入（回款备注：6-7月货款（场景8:含退货冲销））
A22: · 【DE-005】上海晨光文具股份有限公司（九木杂物社）：应收 ¥55,978.70 / 已回 ¥40,542.00 / 差异 ¥15,436.70（回款率 72%）→ 部分回款，建议按销售单逐笔核销回款备注（回款备注：5月货款 单号SO-20260512-024（场景7:逾期15天到账））
A23: · 【DE-006】沃尔玛（中国）投资有限公司：应收 ¥101,507.50 / 已回 ¥17,575.00 / 差异 ¥83,932.50（回款率 17%）→ 部分回款，建议按销售单逐笔核销回款备注）
A24: · 【DE-007】抖音电商（官方旗舰店）：应收 ¥121,600.00 / 已回 ¥134,310.00 / 差异 ¥-12,710.00（回款率 110%）→ 超额回款（疑似预付款 / 跨期冲销），建议确认入账口径（回款备注：7月新品订货预付款（场景4:预付款））
A25: · 【DE-008】TikTok Shop（跨境）：应收 ¥72,650.00 / 已回 ¥19,607.00 / 差异 ¥53,043.00（回款率 27%）→ 部分回款，建议按销售单逐笔核销回款备注（回款备注：TikTok Shop US 6月结算 $2756.00@7.1123 ）
A26: · 【DE-009】广州潮玩前线贸易有限公司：应收 ¥121,281.50 / 已回 ¥54,865.63 / 差异 ¥66,415.87（回款率 45%）→ 部分回款，建议按销售单逐笔核销回款备注（回款备注：7月货款 单号SO-20260720-044（场景5:抹零差异¥0.67）
A27: · 【DE-010】义乌萌物集贸易有限公司：应收 ¥41,467.50 / 已回 ¥40,034.00 / 差异 ¥1,433.50（回款率 97%）→ 小额差异，建议核对抹零 / 手续费 / 四舍五入（回款备注：5月货款（场景10:少付¥1.00））
A28: · 【退货冲销】广州KK馆贸易有限公司 BLIND-02 -30 件，金额 ¥-2,850.00（已计入应收负数，回款含退货冲销，已核销）

Sheet 🎨 艺术家版税结算
A1: 🎨 艺术家版税结算（销售后结算口径）
A2: 版税基数 = 关联SKU对应销售规格的实收金额合计（SUMIF 引用『📦 销售出库』）；应付版税 = 基数 × 分成比例。
A3: 艺术家编码 | B3: 艺术家姓名 | C3: 身份类型 | D3: 关联SKU | E3: 对应销售规格(自动匹配) | F3: 版税基数(销售实收) | G3: 分成比例 | H3: 应付版税(元) | I3: 结算方式 | J3: 状态/备注
A4: AR-001 | B4: 林小喵 | C4: 独立潮玩设计师 | D4: BC-01,BC-07 | E4: OPEN-BC-01 | F4: =ROUND(SUMIF('📦 销售出库'!$E$4:$E$48,"OPEN-BC-01",'📦 销售出库'!$K$4:$K$48),2) | G4: 0.08 | H4: =ROUND(F4*G4,2) | I4: 销售后结算 | J4: BC-07 隐藏款随盲盒/套装随机出货，无独立销售规格，建议按套盒分摊口径另行测算
A5: AR-002 | B5: 陈卷卷 | C5: 自由插画师 | D5: BC-02 | E5: 无直接对应 | F5: 0 | G5: 0.07 | H5: =ROUND(F5*G5,2) | I5: 销售后结算 | J5: BC-02 当期无对应销售规格
A6: AR-003 | B6: 周布布 | C6: 猫主题IP创作者 | D6: BC-03,BC-06 | E6: OPEN-BC-03 | F6: =ROUND(SUMIF('📦 销售出库'!$E$4:$E$48,"OPEN-BC-03",'📦 销售出库'!$K$4:$K$48),2) | G6: 0.08 | H6: =ROUND(F6*G6,2) | I6: 销售后结算 | J6: BC-06 当期无对应销售规格
A7: AR-004 | B7: 刘星野 | C7: 新锐玩具设计师 | D7: BC-04,BC-05 | E7: 无直接对应 | F7: 0 | G7: 0.07 | H7: =ROUND(F7*G7,2) | I7: 销售后结算 | J7: BC-04 当期无对应销售规格；BC-05 当期无对应销售规格
A8: AR-005 | B8: 赵小喵 | C8: 小红书潮玩博主 | D8: BC-08 | E8: 无直接对应 | F8: 0 | G8: 0.1 | H8: =ROUND(F8*G8,2) | I8: 预付+结算 | J8: 含预付 ¥5,000（见合同 CT-2026-005），结算时抵扣；BC-08 隐藏款随盲盒/套装随机出货，无独立销售规格，建议按套盒分摊口径另行测算
A9: AR-006 | B9: 黄多多 | C9: 在校艺术生/草根画手 | D9: BC-ACC-01,BC-ACC-02 | E9: ACC-01、ACC-02 | F9: =ROUND(SUMIF('📦 销售出库'!$E$4:$E$48,"ACC-01",'📦 销售出库'!$K$4:$K$48)+SUMIF('📦 销售出库'!$E$4:$E$48,"ACC-02",'📦 销售出库'!$K$4:$K$48),2) | G9: 0.06 | H9: =ROUND(F9*G9,2) | I9: 销售后结算 | J9: BC-ACC-01 与销售规格 ACC-01 编码不一致（疑缺BC前缀），本期按映射计入，建议与艺术家确认口径；BC-ACC-02 与销售规格 ACC-02 编码不一致（疑缺BC前缀），本期按映射计入，建议与艺术家确认口径
A10: AR-007 | B10: 何梦鹿 | C10: 自由职业插画师 | D10: BC-ACC-03,BC-ACC-04 | E10: ACC-04 | F10: =ROUND(SUMIF('📦 销售出库'!$E$4:$E$48,"ACC-04",'📦 销售出库'!$K$4:$K$48),2) | G10: 0.06 | H10: =ROUND(F10*G10,2) | I10: 销售后结算 | J10: BC-ACC-03 当期无对应销售规格；BC-ACC-04 与销售规格 ACC-04 编码不一致（疑缺BC前缀），本期按映射计入，建议与艺术家确认口径
A11: AR-008 | B11: 杨桃桃 | C11: 纹身师兼玩具涂装师 | D11: BC-ACC-05,BC-ACC-06 | E11: ACC-06 | F11: =ROUND(SUMIF('📦 销售出库'!$E$4:$E$48,"ACC-06",'📦 销售出库'!$K$4:$K$48),2) | G11: 0.06 | H11: =ROUND(F11*G11,2) | I11: 销售后结算 | J11: BC-ACC-05 当期无对应销售规格；BC-ACC-06 与销售规格 ACC-06 编码不一致（疑缺BC前缀），本期按映射计入，建议与艺术家确认口径
A12: 合计 | F12: =SUM(F4:F11) | H12: =SUM(H4:H11)

Sheet 🎪 展会核算
A1: 🎪 展会核算（3 场）
A2: 毛利率 = 净收入 ÷ 总收入；收款方式为现场收款渠道（微信/支付宝/POS）。
A3: 活动编码 | B3: 活动名称 | C3: 开始日期 | D3: 结束日期 | E3: 地点 | F3: 收入类型 | G3: 总收入 | H3: 费用 | I3: 净收入 | J3: 收款方式 | K3: 毛利率
A4: CTE-001 | B4: CTE玩具展 | C4: 45915 | D4: 45917 | E4: 深圳 | F4: 现场零售+预售 | G4: 15680 | H4: 2340 | I4: 13340 | J4: 微信/支付宝/POS | K4: =IF(G4=0,"",I4/G4)
A5: HTE-001 | B5: HTE杭州潮玩展 | C5: 46108 | D5: 46110 | E5: 杭州 | F5: 现场零售 | G5: 12350 | H5: 1860 | I5: 10490 | J5: 微信/支付宝 | K5: =IF(G5=0,"",I5/G5)
A6: POP-001 | B6: 济南圣诞快闪店 | C6: 45997 | D6: 46017 | E6: 济南 | F6: 快闪店零售+吊卡首发 | G6: 44118 | H6: 5200 | I6: 38918 | J6: 微信/支付宝/POS | K6: =IF(G6=0,"",I6/G6)
A7: 合计 | G7: =SUM(G4:G6) | H7: =SUM(H4:H6) | I7: =SUM(I4:I6) | K7: =IF(G7=0,"",I7/G7)

Sheet 📊 Dashboard
A1: 📊 BabyCat 财务对账 Dashboard
A2: 数据期间 2026年5—7月 · 对账基准日 2026-08-11（F31 可修改，账龄自动重算） · 全部指标由公式自动计算
D4: 总应收（销售实收） | F4: 总已回（银行回款） | H4: 净差异（应收-已回） | J4: 对账完成率
D5: =SUM('🔗 经销商对账'!$C$4:$C$13) | F5: =SUM('🔗 经销商对账'!$E$4:$E$13) | H5: =A5-C5 | J5: =IF(A5=0,0,C5/A5)
A7: ① 经销商应收 vs 已回（元） | K7: ② 月度销售/回款趋势（2026年5-7月）
K8: 月份 | L8: 销售额(元) | M8: 回款额(元)
K9: 2026-05 | L9: =SUMIFS('📦 销售出库'!$K$4:$K$48,'📦 销售出库'!$B$4:$B$48,">="&DATE(2026,5,1),'📦 销售出库'!$B$4:$B$48,"<"&DATE(2026,6,1)) | M9: =SUMIFS('💰 银行回款'!$D$4:$D$25,'💰 银行回款'!$B$4:$B$25,">="&DATE(2026,5,1),'💰 银行回款'!$B$4:$B$25,"<"&DATE(2026,6,1))
K10: 2026-06 | L10: =SUMIFS('📦 销售出库'!$K$4:$K$48,'📦 销售出库'!$B$4:$B$48,">="&DATE(2026,6,1),'📦 销售出库'!$B$4:$B$48,"<"&DATE(2026,7,1)) | M10: =SUMIFS('💰 银行回款'!$D$4:$D$25,'💰 银行回款'!$B$4:$B$25,">="&DATE(2026,6,1),'💰 银行回款'!$B$4:$B$25,"<"&DATE(2026,7,1))
K11: 2026-07 | L11: =SUMIFS('📦 销售出库'!$K$4:$K$48,'📦 销售出库'!$B$4:$B$48,">="&DATE(2026,7,1),'📦 销售出库'!$B$4:$B$48,"<"&DATE(2027,1,1)) | M11: =SUMIFS('💰 银行回款'!$D$4:$D$25,'💰 银行回款'!$B$4:$B$25,">="&DATE(2026,7,1),'💰 银行回款'!$B$4:$B$25,"<"&DATE(2027,1,1))
K12: 合计 | L12: =SUM(L9:L11) | M12: =SUM(M9:M11)
A29: ③ 应收账款账龄分析（按销售到期日口径，元）
A30: 账龄区间 | B30: 应收金额(元) | C30: 占比
A31: 未到期(信用期内) | B31: =SUMPRODUCT(('📦 销售出库'!$M$4:$M$48>$F$31)*('📦 销售出库'!$K$4:$K$48)) | C31: =IF($B$36=0,"",B31/$B$36) | E31: 对账基准日 | F31: =DATE(2026,8,11) | G31: （修改后账龄自动重算）
A32: 0-30天 | B32: =SUMPRODUCT(('📦 销售出库'!$M$4:$M$48<=$F$31)*('📦 销售出库'!$M$4:$M$48>$F$31-30)*('📦 销售出库'!$K$4:$K$48)) | C32: =IF($B$36=0,"",B32/$B$36)
A33: 31-60天 | B33: =SUMPRODUCT(('📦 销售出库'!$M$4:$M$48<=$F$31-30)*('📦 销售出库'!$M$4:$M$48>$F$31-60)*('📦 销售出库'!$K$4:$K$48)) | C33: =IF($B$36=0,"",B33/$B$36)
A34: 61-90天 | B34: =SUMPRODUCT(('📦 销售出库'!$M$4:$M$48<=$F$31-60)*('📦 销售出库'!$M$4:$M$48>$F$31-90)*('📦 销售出库'!$K$4:$K$48)) | C34: =IF($B$36=0,"",B34/$B$36)
A35: 90天以上 | B35: =SUMPRODUCT(('📦 销售出库'!$M$4:$M$48<=$F$31-90)*('📦 销售出库'!$K$4:$K$48)) | C35: =IF($B$36=0,"",B35/$B$36)
A36: 合计 | B36: =SUM(B31:B35) | C36: =IF($B$36=0,"",B36/B36)
A38: 说明：账龄按销售出库到期日与基准日计算（退货冲销负数计入对应区间）；KPI 中净差异为负表示超额回款（预付款/跨期冲销）；完整明细见『🔗 经销商对账』『📦 销售出库』『💰 银行回款』。
A40: ④ 经销商对账镜像（供图表引用，公式自动同步）
A41: 经销商编码 | B41: 经销商名称 | C41: 应收 | D41: 已回
A42: ='🔗 经销商对账'!A4 | B42: ='🔗 经销商对账'!B4 | C42: ='🔗 经销商对账'!C4 | D42: ='🔗 经销商对账'!E4
A43: ='🔗 经销商对账'!A5 | B43: ='🔗 经销商对账'!B5 | C43: ='🔗 经销商对账'!C5 | D43: ='🔗 经销商对账'!E5
A44: ='🔗 经销商对账'!A6 | B44: ='🔗 经销商对账'!B6 | C44: ='🔗 经销商对账'!C6 | D44: ='🔗 经销商对账'!E6
A45: ='🔗 经销商对账'!A7 | B45: ='🔗 经销商对账'!B7 | C45: ='🔗 经销商对账'!C7 | D45: ='🔗 经销商对账'!E7
A46: ='🔗 经销商对账'!A8 | B46: ='🔗 经销商对账'!B8 | C46: ='🔗 经销商对账'!C8 | D46: ='🔗 经销商对账'!E8
A47: ='🔗 经销商对账'!A9 | B47: ='🔗 经销商对账'!B9 | C47: ='🔗 经销商对账'!C9 | D47: ='🔗 经销商对账'!E9
A48: ='🔗 经销商对账'!A10 | B48: ='🔗 经销商对账'!B10 | C48: ='🔗 经销商对账'!C10 | D48: ='🔗 经销商对账'!E10
A49: ='🔗 经销商对账'!A11 | B49: ='🔗 经销商对账'!B11 | C49: ='🔗 经销商对账'!C11 | D49: ='🔗 经销商对账'!E11
A50: ='🔗 经销商对账'!A12 | B50: ='🔗 经销商对账'!B12 | C50: ='🔗 经销商对账'!C12 | D50: ='🔗 经销商对账'!E12
A51: ='🔗 经销商对账'!A13 | B51: ='🔗 经销商对账'!B13 | C51: ='🔗 经销商对账'!C13 | D51: ='🔗 经销商对账'!E13

Sheet 📋 合同发票台账
A1: 📋 合同发票台账（15 份）
A2: 进项/销项发票为示例登记；开票状态自动判断：存在发票号 → 已开票，否则 → 待开票。
A3: 合同编号 | B3: 签约方 | C3: 合同名称 | D3: 签署日期 | E3: 到期日期 | F3: 状态 | G3: 备注 | H3: 进项发票 | I3: 销项发票 | J3: 开票状态
A4: CT-2025-001 | B4: 摩点平台 | C4: 平台服务协议 | D4: 45839 | E4: 46204 | F4: 执行中 | H4: JX-2026-203 | J4: =IF(OR(H4<>"",I4<>""),"已开票","待开票")
A5: CT-2025-002 | B5: 名创优品 | C5: 经销合作协议 | D5: 45901 | E5: 46266 | F5: 执行中 | G5: 含寄售条款 | I5: INV-2026-101 | J5: =IF(OR(H5<>"",I5<>""),"已开票","待开票")
A6: CT-2025-003 | B6: 酷乐潮玩 | C6: 经销合作协议 | D6: 45915 | E6: 46280 | F6: 执行中 | G6: 含寄售条款 | I6: INV-2026-102 | J6: =IF(OR(H6<>"",I6<>""),"已开票","待开票")
A7: CT-2025-004 | B7: TOPTOY | C7: 经销合作协议 | D7: 45931 | E7: 46296 | F7: 执行中 | G7: 含寄售条款 | I7: INV-2026-103 | J7: =IF(OR(H7<>"",I7<>""),"已开票","待开票")
A8: CT-2025-005 | B8: KKV | C8: 经销合作协议 | D8: 45945 | E8: 46310 | F8: 执行中 | G8: 含寄售条款 | I8: INV-2026-104 | J8: =IF(OR(H8<>"",I8<>""),"已开票","待开票")
A9: CT-2025-006 | B9: 九木杂物社 | C9: 经销合作协议 | D9: 45962 | E9: 46327 | F9: 执行中 | G9: 含寄售条款 | I9: INV-2026-105 | J9: =IF(OR(H9<>"",I9<>""),"已开票","待开票")
A10: CT-2025-007 | B10: 沃尔玛 | C10: 供货合同 | D10: 45976 | E10: 46341 | F10: 执行中 | G10: 买断制 | I10: INV-2026-106 | J10: =IF(OR(H10<>"",I10<>""),"已开票","待开票")
A11: CT-2025-008 | B11: 广州潮玩前线 | C11: 区域经销合同 | D11: 45992 | E11: 46357 | F11: 执行中 | G11: 华南区域 | I11: INV-2026-107 | J11: =IF(OR(H11<>"",I11<>""),"已开票","待开票")
A12: CT-2025-009 | B12: 义乌萌物集 | C12: 区域经销合同 | D12: 46006 | E12: 46371 | F12: 执行中 | G12: 华东区域 | I12: INV-2026-108 | J12: =IF(OR(H12<>"",I12<>""),"已开票","待开票")
A13: CT-2026-001 | B13: 林小喵 | C13: 艺术家合作协议 | D13: 45809 | E13: 46174 | F13: 执行中 | G13: BC-01,BC-07 分成8% | H13: JX-2026-204 | J13: =IF(OR(H13<>"",I13<>""),"已开票","待开票")
A14: CT-2026-002 | B14: 陈卷卷 | C14: 艺术家合作协议 | D14: 45823 | E14: 46188 | F14: 执行中 | G14: BC-02 分成7% | H14: JX-2026-205 | J14: =IF(OR(H14<>"",I14<>""),"已开票","待开票")
A15: CT-2026-003 | B15: 周布布 | C15: 艺术家合作协议 | D15: 45839 | E15: 46204 | F15: 执行中 | G15: BC-03,BC-06 分成8% | H15: JX-2026-206 | J15: =IF(OR(H15<>"",I15<>""),"已开票","待开票")
A16: CT-2026-004 | B16: 刘星野 | C16: 艺术家合作协议 | D16: 45853 | E16: 46218 | F16: 执行中 | G16: BC-04,BC-05 分成7% | H16: JX-2026-207 | J16: =IF(OR(H16<>"",I16<>""),"已开票","待开票")
A17: CT-2026-005 | B17: 赵小喵 | C17: 艺术家合作协议 | D17: 45870 | E17: 46235 | F17: 执行中 | G17: BC-08 分成10% 含预付¥5000 | H17: JX-2026-208 | J17: =IF(OR(H17<>"",I17<>""),"已开票","待开票")

Sheet 📦 代账交接清单
A1: 📦 代账交接清单 — 菲格洛亚 FIGUEROA（BabyCat IP）
A2: 交接期间：2026年5月—7月（含 2025 年摩点众筹 / 展会等历史事项备查） · 对账基准日：2026-08-11 · 编制：财务部
A4: ① 期间业务概况
A5: · 销售出库单 45 笔（含退货冲销 1 笔，负值已冲减应收）
A6: · 银行回款 22 笔，全部自动匹配到经销商（匹配率 100%）
A7: · 经销商 10 家（连锁零售 / 电商平台 / 区域经销 / 海外跨境）
A8: · 摩点众筹三阶段结算全部到账；支持明细抽样 112 笔
A9: · 潮玩展会 3 场（CTE / HTE / 济南快闪）
A10: · 合同台账 14 份，其中艺术家合作协议 5 份
A12: ② 关键对账结果（公式自动引用各分表）
A13: 项目 | B13: 数值
A14: 经销商总应收（销售实收） | B14: =SUM('🔗 经销商对账'!$C$4:$C$13)
A15: 经销商总已回（银行回款） | B15: =SUM('🔗 经销商对账'!$E$4:$E$13)
A16: 净差异（应收 - 已回） | B16: =B14-B15
A17: 已匹配家数 | B17: =COUNTIF('🔗 经销商对账'!$G$4:$G$13,"已匹配")
A18: 部分/超额回款家数 | B18: =COUNTIF('🔗 经销商对账'!$G$4:$G$13,"部分回款")+COUNTIF('🔗 经销商对账'!$G$4:$G$13,"超额回款")
A19: 未回款家数 | B19: =COUNTIF('🔗 经销商对账'!$G$4:$G$13,"未回款")
A20: 摩点众筹已到账合计 | B20: ='🎯 摩点众筹结算'!F8
A21: 展会净收入合计 | B21: ='🎪 展会核算'!I7
A22: 艺术家版税应付合计 | B22: ='🎨 艺术家版税结算'!H12
A23: 销售单总数 / 回款笔数 | B23: =COUNTA('📦 销售出库'!$A$4:$A$48)&" 笔 / "&COUNTA('💰 银行回款'!$A$4:$A$25)&" 笔"
A25: ③ 文档交接清单（随附电子版/纸质件）
A26: ☐ 银行回单 / 对账单：22 笔（『💰 银行回款』），含回款备注核销说明
A27: ☐ 销售出库单：45 笔（『📦 销售出库』），含退货冲销 -30 件（品质问题，DE-004）
A28: ☐ 经销商对账确认函：10 家（『🔗 经销商对账』），未对平项见待核对清单
A29: ☐ 摩点众筹结算单：3 阶段（首款/中款/尾款），支持明细抽样 112 笔
A30: ☐ 展会收入台账：3 场（CTE / HTE / 济南快闪），含现场收款流水
A31: ☐ 合同台账：15 份（『📋 合同发票台账』），含艺术家合作协议 5 份
A32: ☐ 发票：销项 INV-2026-xxx 系列（经销/供货合同）、进项 JX-2026-xxx 系列（平台/艺术家）
A33: ☐ 费用报销单：10 笔（『🧾 费用报销审核』），OA 审批号已登记
A34: ☐ 现金日记账：13 笔现金流示例（『💵 现金日记账』）
A36: ④ 待办 / 风险事项
A37: 1. 沃尔玛（DE-006）6 月追单账期届满未回，金额较大，建议 8 月优先催收；
... A46: ⑤ 交接确认
A47: 移交人（菲格洛亚 财务部） | B47: ＿＿＿＿＿＿＿（签名）
A48: 接收人（代账公司） | B48: ＿＿＿＿＿＿＿（签名）
A49: 交接日期 | B49: ＿＿＿＿＿＿＿＿＿
A50: 备注 | B50: 本清单与各分表共同构成期间账务交接依据，如有异议请在 5 个工作日内提出。

Sheet 💵 现金日记账
A1: 💵 现金日记账（示例：众筹 / 展会 / 回款现金流）
A2: 示例数据基于摩点到账、展会收支与经销商回款；余额列按累计公式自动计算。
A3: 日期 | B3: 凭证号 | C3: 摘要 | D3: 收入 | E3: 支出 | F3: 余额 | G3: 备注
A4: 45879 | B4: CJ-001 | C4: 摩点众筹首款到账 | D4: 39778 | E4: 0 | F4: =D4-E4 | G4: MD-SETTLE-01（首款50%）
A5: 45917 | B5: CJ-002 | C5: CTE玩具展现场收款 | D5: 13340 | E5: 0 | F5: =F4+D5-E5 | G5: 微信/支付宝/POS
A6: 45920 | B6: CJ-003 | C6: CTE玩具展场地及物料费用 | D6: 0 | E6: 2340 | F6: =F5+D6-E6 | G6: 展会成本
A7: 45986 | B7: CJ-004 | C7: 摩点众筹中款到账 | D7: 25067 | E7: 0 | F7: =F6+D7-E7 | G7: MD-SETTLE-02（中款30%）
A8: 46017 | B8: CJ-005 | C8: 济南圣诞快闪店零售收款 | D8: 44118 | E8: 0 | F8: =F7+D8-E8 | G8: 含冬季吊卡首发342个
A9: 46019 | B9: CJ-006 | C9: 快闪店场地及物料费用 | D9: 0 | E9: 5200 | F9: =F8+D9-E9 | G9: POP-001
A10: 46065 | B10: CJ-007 | C10: 摩点众筹尾款到账 | D10: 16711 | E10: 0 | F10: =F9+D10-E10 | G10: MD-SETTLE-03（尾款20%）
A11: 46110 | B11: CJ-008 | C11: HTE杭州潮玩展收款 | D11: 10490 | E11: 0 | F11: =F10+D11-E11 | G11: 微信/支付宝
A12: 46112 | B12: CJ-009 | C12: HTE展会费用 | D12: 0 | E12: 1860 | F12: =F11+D12-E12 | G12: HTE-001
A13: 46193 | B13: CJ-010 | C13: 名创优品5月试产回款 | D13: 53820.8 | E13: 0 | F13: =F12+D13-E13 | G13: PM-20260620-010
A14: 46204 | B14: CJ-011 | C14: 抖音电商订货预付款 | D14: 30000 | E14: 0 | F14: =F13+D14-E14 | G14: PM-20260701-003（预付款）
A15: 46235 | B15: CJ-012 | C15: 名创优品6月货款回款 | D15: 163348 | E15: 0 | F15: =F14+D15-E15 | G15: PM-20260801-001（多单合并）
A16: 46242 | B16: CJ-013 | C16: 名创优品7月货款回款 | D16: 72680 | E16: 0 | F16: =F15+D16-E16 | G16: PM-20260808-013
B17: 本期合计 | D17: =SUM(D4:D16) | E17: =SUM(E4:E16) | F17: =F16

Sheet 🧾 费用报销审核
A1: 🧾 费用报销审核（示例 10 笔）
A2: 审核状态自动判断：报销金额 ≠ 发票金额 → 发票差异（红）；缺飞书 OA 审批号 → 待OA审批（黄）；其余 → 通过。
A3: 报销单号 | B3: 申请日期 | C3: 申请人 | D3: 费用类别 | E3: 报销金额 | F3: 发票金额 | G3: 发票号码 | H3: 飞书OA审批号 | I3: 审核状态 | J3: 备注
A4: EX-2026-001 | B4: 46181 | C4: 陈卷卷 | D4: 展会差旅费(CTE玩具展) | E4: 2340 | F4: 2340 | G4: EZZ-2026-1101 | H4: OA-2026-0102 | I4: =IF(ABS(E4-F4)>0.01,"发票差异",IF(H4="","待OA审批","通过")) | J4: 高铁+住宿
A5: EX-2026-002 | B5: 46188 | C5: 周布布 | D5: 展会物料制作(济南快闪) | E5: 5200 | F5: 5200 | G5: EZZ-2026-1188 | H5: OA-2026-0115 | I5: =IF(ABS(E5-F5)>0.01,"发票差异",IF(H5="","待OA审批","通过")) | J5: POP-001 现场物料
A6: EX-2026-003 | B6: 46195 | C6: 林小喵 | D6: 设计服务费(角色设定) | E6: 8000 | F6: 8000 | G6: EZZ-2026-1201 | H6: OA-2026-0120 | I6: =IF(ABS(E6-F6)>0.01,"发票差异",IF(H6="","待OA审批","通过")) | J6: 新系列角色设定
A7: EX-2026-004 | B7: 46205 | C7: 刘星野 | D7: 打样费(新系列) | E7: 3500 | F7: 3200 | G7: EZZ-2026-1233 | H7: OA-2026-0129 | I7: =IF(ABS(E7-F7)>0.01,"发票差异",IF(H7="","待OA审批","通过")) | J7: 发票金额与报销不一致
A8: EX-2026-005 | B8: 46213 | C8: 赵小喵 | D8: 小红书推广费 | E8: 6000 | F8: 6000 | G8: EZZ-2026-1250 | H8: OA-2026-0131 | I8: =IF(ABS(E8-F8)>0.01,"发票差异",IF(H8="","待OA审批","通过")) | J8: 达人笔记投放
A9: EX-2026-006 | B9: 46221 | C9: 黄多多 | D9: 快递物流费(盲盒发货) | E9: 1860 | F9: 1860 | G9: EZZ-2026-1266 | H9: OA-2026-0137 | I9: =IF(ABS(E9-F9)>0.01,"发票差异",IF(H9="","待OA审批","通过")) | J9: 众筹补发货
A10: EX-2026-007 | B10: 46228 | C10: 何梦鹿 | D10: 办公用品 | E10: 458 | F10: 458 | G10: 无发票 | I10: =IF(ABS(E10-F10)>0.01,"发票差异",IF(H10="","待OA审批","通过")) | J10: 零星采购，OA 未归档
A11: EX-2026-008 | B11: 46235 | C11: 杨桃桃 | D11: 打车费(广州出差) | E11: 320 | F11: 300 | G11: EZZ-2026-1300 | H11: OA-2026-0142 | I11: =IF(ABS(E11-F11)>0.01,"发票差异",IF(H11="","待OA审批","通过")) | J11: 行程单与发票差20元
A12: EX-2026-009 | B12: 46239 | C12: 陈卷卷 | D12: 平台服务费(摩点手续费) | E12: 5205.7 | F12: 5205.7 | G12: EZZ-2026-1311 | H12: OA-2026-0145 | I12: =IF(ABS(E12-F12)>0.01,"发票差异",IF(H12="","待OA审批","通过")) | J12: 服务费6%测算
A13: EX-2026-010 | B13: 46242 | C13: 林小喵 | D13: 餐饮招待(渠道洽谈) | E13: 1280 | F13: 1280 | G13: EZZ-2026-1320 | H13: OA-2026-0148 | I13: =IF(ABS(E13-F13)>0.01,"发票差异",IF(H13="","待OA审批","通过")) | J13: 名创优品商务洽谈
